Workbook
Name BURN: 'P&L_Data'!$J$2:$J$25
Name REVENUE: 'P&L_Data'!$B$2:$B$25

Sheet P&L_Data
A1: Month | B1: Revenue | C1: COGS | D1: OpEx | E1: Cash_in | F1: Cash_out | G1: Gross Profit | H1: Gross Margin % | I1: Net Profit | J1: Monthly Burn | K1: Cumulative Cash | M1: Starting Cash
A2: 45292 | B2: 157500 | C2: 47250 | D2: 90000 | E2: 157500 | F2: 137250 | G2: =B2-C2 -> 110250 | H2: =IF(B2=0,0,(B2-C2)/B2) -> 0.7 | I2: =B2-C2-D2 -> 20250 | J2: =F2-E2 -> -20250 | K2: =$N$1 + J2 -> -20250
A3: 45323 | B3: 157500 | C3: 49612.5 | D3: 91800 | E3: 165375 | F3: 141412.5 | G3: =B3-C3 -> 107887.5 | H3: =IF(B3=0,0,(B3-C3)/B3) -> 0.685 | I3: =B3-C3-D3 -> 16087.5 | J3: =F3-E3 -> -23962.5 | K3: =K2+J3 -> -44212.5
A4: 45352 | B4: 157500 | C4: 52093.12 | D4: 93600 | E4: 173643.75 | F4: 145693.12 | G4: =B4-C4 -> 105406.88 | H4: =IF(B4=0,0,(B4-C4)/B4) -> 0.66925003 | I4: =B4-C4-D4 -> 11806.88 | J4: =F4-E4 -> -27950.63 | K4: =K3+J4 -> -72163.13
A5: 45383 | B5: 157500 | C5: 54697.78 | D5: 95400 | E5: 182325.94 | F5: 150097.78 | G5: =B5-C5 -> 102802.22 | H5: =IF(B5=0,0,(B5-C5)/B5) -> 0.65271251 | I5: =B5-C5-D5 -> 7402.22 | J5: =F5-E5 -> -32228.16 | K5: =K4+J5 -> -104391.29
A6: 45413 | B6: 157500 | C6: 57432.67 | D6: 97200 | E6: 191442.23 | F6: 154632.67 | G6: =B6-C6 -> 100067.33 | H6: =IF(B6=0,0,(B6-C6)/B6) -> 0.63534813 | I6: =B6-C6-D6 -> 2867.33 | J6: =F6-E6 -> -36809.56 | K6: =K5+J6 -> -141200.85
A7: 45444 | B7: 157500 | C7: 60304.3 | D7: 99000 | E7: 201014.34 | F7: 159304.3 | G7: =B7-C7 -> 97195.7 | H7: =IF(B7=0,0,(B7-C7)/B7) -> 0.61711556 | I7: =B7-C7-D7 -> -1804.3 | J7: =F7-E7 -> -41710.04 | K7: =K6+J7 -> -182910.89
A8: 45474 | B8: 157500 | C8: 63319.52 | D8: 100800 | E8: 211065.05 | F8: 164119.52 | G8: =B8-C8 -> 94180.48 | H8: =IF(B8=0,0,(B8-C8)/B8) -> 0.5979713 | I8: =B8-C8-D8 -> -6619.52 | J8: =F8-E8 -> -46945.53 | K8: =K7+J8 -> -229856.42
A9: 45505 | B9: 157500 | C9: 66485.49 | D9: 102600 | E9: 221618.32 | F9: 169085.49 | G9: =B9-C9 -> 91014.51 | H9: =IF(B9=0,0,(B9-C9)/B9) -> 0.5778699 | I9: =B9-C9-D9 -> -11585.49 | J9: =F9-E9 -> -52532.83 | K9: =K8+J9 -> -282389.25
A10: 45536 | B10: 157500 | C10: 69809.77 | D10: 104400 | E10: 232699.24 | F10: 174209.77 | G10: =B10-C10 -> 87690.23 | H10: =IF(B10=0,0,(B10-C10)/B10) -> 0.55676337 | I10: =B10-C10-D10 -> -16709.77 | J10: =F10-E10 -> -58489.47 | K10: =K9+J10 -> -340878.72
A11: 45566 | B11: 157500 | C11: 73299.06 | D11: 106200 | E11: 244334.2 | F11: 179499.06 | G11: =B11-C11 -> 84200.94 | H11: =IF(B11=0,0,(B11-C11)/B11) -> 0.53460914 | I11: =B11-C11-D11 -> -21999.06 | J11: =F11-E11 -> -64835.14 | K11: =K10+J11 -> -405713.86
A12: 45597 | B12: 157500 | C12: 76965.57 | D12: 108000 | E12: 256551.91 | F12: 184965.57 | G12: =B12-C12 -> 80534.43 | H12: =IF(B12=0,0,(B12-C12)/B12) -> 0.51132971 | I12: =B12-C12-D12 -> -27465.57 | J12: =F12-E12 -> -71586.34 | K12: =K11+J12 -> -477300.2
A13: 45627 | B13: 157500 | C13: 80813.85 | D13: 109800 | E13: 269379.51 | F13: 190613.85 | G13: =B13-C13 -> 76686.15 | H13: =IF(B13=0,0,(B13-C13)/B13) -> 0.48689619 | I13: =B13-C13-D13 -> -33113.85 | J13: =F13-E13 -> -78765.66 | K13: =K12+J13 -> -556065.86
A14: 45658 | B14: 157500 | C14: 84854.55 | D14: 111600 | E14: 282848.49 | F14: 196454.55 | G14: =B14-C14 -> 72645.45 | H14: =IF(B14=0,0,(B14-C14)/B14) -> 0.46124095 | I14: =B14-C14-D14 -> -38954.55 | J14: =F14-E14 -> -86393.94 | K14: =K13+J14 -> -642459.8
... A25: 45992 | B25: 157500 | C25: 145129.5 | D25: 131400 | E25: 483764.99 | F25: 276529.5 | G25: =B25-C25 -> 12370.5 | H25: =IF(B25=0,0,(B25-C25)/B25) -> 0.078542857 | I25: =B25-C25-D25 -> -119029.5 | J25: =F25-E25 -> -207235.49 | K25: =K24+J25 -> -2251426.9
B26: =SUM(B2:B25) -> 3780000 | C26: =SUM(C2:C25) -> 2103524.1 | D26: =SUM(D2:D25) -> 2656800 | E26: =SUM(E2:E25) -> 7011751 | F26: =SUM(F2:F25) -> 4760324.1 | G26: =B26-C26 -> 1676475.9 | I26: =SUM(I2:I25) -> -980324.08 | J26: =SUM(J2:J25) -> -2251426.9 | K26: =SUM(K2:K25) -> -18979721
A30: Revenue | C30: =B26 -> 3780000
A31: COGS | C31: =C26 -> 2103524.1
A32: Gross Profit | C32: =G26 -> 1676475.9
A34: Operating Expenses:
A35: Payroll
A36: Marketing
A37: Vendor Expenses | C37: =Vendor_Expenses!C1 -> 179427
A38: Other OPEX
A40: EBITDA | C40: =C32-(C35+C36+C37+C38) -> 1497048.9
A41: Taxes | C41: =C40*0.21 -> 314380.27 | D41: used 21% since the tax is not specified
A42: Net Income | C42: =C40-C41 -> 1182668.6

Sheet Vendor_Expenses
A1: Vendor | B1: Description | C1: =SUM(C3:C32) -> 179427 | D1: Fixed/Variable | E1: Core/Discretionary | F1: % of Total Spend | G1: Cut Flag | I1: Eliminable Spend | J1: If vendor discretionary, amount is eliminable
A2: OpenAI | B2: AI compute for 100x | C2: Monthly_Amount | D2: Variable | E2: Core | F2: =C3 / SUM($C$2:$C$31) -> 0.0067949588 | G2: =IF(E2="Discretionary", "Yes", "No") -> No | I2: =IF(E2="Discretionary", C2, 0) -> 0 | J2: If core, eliminable = 0
A3: AWS | B3: Cloud hosting | C3: 1191 | D3: Variable | E3: Core | F3: =C4 / SUM($C$2:$C$31) -> 0.033706647 | G3: =IF(E3="Discretionary", "Yes", "No") -> No | I3: =IF(E3="Discretionary", C3, 0) -> 0
A4: GCP | B4: Backup cloud provider | C4: 5908 | D4: Fixed | E4: Core | F4: =C5 / SUM($C$2:$C$31) -> 0.047347912 | G4: =IF(E4="Discretionary", "Yes", "No") -> No | I4: =IF(E4="Discretionary", C4, 0) -> 0
A5: Azure | B5: Redundancy cloud zone | C5: 8299 | D5: Fixed | E5: Core | F5: =C6 / SUM($C$2:$C$31) -> 0.013898001 | G5: =IF(E5="Discretionary", "Yes", "No") -> No | I5: =IF(E5="Discretionary", C5, 0) -> 0
A6: Snowflake | B6: Data warehouse | C6: 2436 | D6: Fixed | E6: Core | F6: =C7 / SUM($C$2:$C$31) -> 0.02270121 | G6: =IF(E6="Discretionary", "Yes", "No") -> No | I6: =IF(E6="Discretionary", C6, 0) -> 0
A7: Databricks | B7: ML pipelines | C7: 3979 | D7: Fixed | E7: Core | F7: =C8 / SUM($C$2:$C$31) -> 0.038230914 | G7: =IF(E7="Discretionary", "Yes", "No") -> No | I7: =IF(E7="Discretionary", C7, 0) -> 0
A8: Slack | B8: Team comms | C8: 6701 | D8: Fixed | E8: Core | F8: =C9 / SUM($C$2:$C$31) -> 0.017355386 | G8: =IF(E8="Discretionary", "Yes", "No") -> No | I8: =IF(E8="Discretionary", C8, 0) -> 0
A9: Zoom | B9: Licences & webinars | C9: 3042 | D9: Fixed | E9: Discretionay | F9: =C10 / SUM($C$2:$C$31) -> 0.037300958 | G9: =IF(E9="Discretionary", "Yes", "No") -> No | I9: =IF(E9="Discretionary", C9, 0) -> 0
A10: Notion | B10: Knowledge base | C10: 6538 | D10: Fixed | E10: Core | F10: =C11 / SUM($C$2:$C$31) -> 0.033050543 | G10: =IF(E10="Discretionary", "Yes", "No") -> No | I10: =IF(E10="Discretionary", C10, 0) -> 0
A11: Airtable | B11: Ops database | C11: 5793 | D11: Fixed | E11: Core | F11: =C12 / SUM($C$2:$C$31) -> 0.039491776 | G11: =IF(E11="Discretionary", "Yes", "No") -> No | I11: =IF(E11="Discretionary", C11, 0) -> 0
A12: QuickBooks | B12: Accounting software | C12: 6922 | D12: Fixed | E12: Core | F12: =C13 / SUM($C$2:$C$31) -> 0.03936626 | G12: =IF(E12="Discretionary", "Yes", "No") -> No | I12: =IF(E12="Discretionary", C12, 0) -> 0
A13: Stripe Fees | B13: Payment processing | C13: 6900 | D13: Variable | E13: Core | F13: =C14 / SUM($C$2:$C$31) -> 0.037477821 | G13: =IF(E13="Discretionary", "Yes", "No") -> No | I13: =IF(E13="Discretionary", C13, 0) -> 0
A14: Mercury Bank Fees | B14: Wire & FX fees | C14: 6569 | D14: Variable | E14: Core | F14: =C15 / SUM($C$2:$C$31) -> 0.019363636 | G14: =IF(E14="Discretionary", "Yes", "No") -> No | I14: =IF(E14="Discretionary", C14, 0) -> 0
... A31: Figma | B31: Product design | C31: 1562 | D31: Fixed | E31: Core | F31: =C32 / SUM($C$2:$C$31) -> 0.023676809 | G31: =IF(E31="Discretionary", "Yes", "No") -> No | I31: =IF(E31="Discretionary", C31, 0) -> 0
C32: 4150
A35: Total Spend | B35: =SUM(C3:C32) -> 179427
A36: Core Spend | B36: =SUMIF(E2:E31,"CORE",C3:C32) -> 107525
A37: Discretionary | B37: =SUMIF(E2:E31,"DISCRETIONARY",C3:C32) -> 0
A38: Eliminable | B38: =SUM(I2:I32) -> 0

Sheet Dashboard
A1: Total Revenue | B1: =SUM('P&L_Data'!B2:B25) -> 3780000
A2: Total COGS | B2: =SUM('P&L_Data'!C2:C25) -> 2103524.1
A3: Total OpEx | B3: =SUM('P&L_Data'!D2:D25) -> 2656800 | C3: Key Metrics
A4: Total Net Profit | B4: =SUM('P&L_Data'!I2:I25) -> -980324.08
A6: Ending Cash | B6: {=INDEX('P&L_Data'!K2:K25,COUNTA('P&L_Data'!A2:A25))} -> -2251426.9 | C6: Cash On Hand
A8: Total Cash In | B8: =SUM('P&L_Data'!E2:E25) -> 7011751
A9: Total Cash Out | B9: =SUM('P&L_Data'!F2:F25) -> 4760324.1 | C9: Liquidity Bridge Inputs
A10: Net Cash Change | B10: =SUM('P&L_Data'!J2:J25) -> -2251426.9
A12: Average Monthly Burn | B12: =AVERAGE('P&L_Data'!J2:J25) -> -93809.455
A13: Current Cash | B13: =B6 -> -2251426.9 | C13: Runway
A14: Runway (Months) | B14: =IF(B12=0,0,B13/ABS(B12)) -> -24

Sheet Compliance_Calendar
A1: Jurisdiction | B1: Legal Entity | C1: Filing | D1: Reason | E1: Frequency | F1: Due Date | G1: Risk Level | H1: Status
A2: US | B2: C-Corp | C2: Form 941 payroll | D2: Federal payroll filing | E2: Quarterly | F2: 04/30/2024 | G2: 🟡 Medium | H2: ✅ Upcoming
A3: US | B3: C-Corp | C3: Form 1120 | D3: Annual corporate income tax return | E3: Annually | F3: 04/15/2025 | G3: 🔴 High | H3: ✅ Upcoming
A4: US | B4: LP | C4: Send Annual K-1s | D4: Tax statement for partners | E4: Annually | F4: 03/15/2025 | G4: 🔴 High | H4: ✅ Upcoming
A5: India | B5: Pvt. Ltd. | C5: GST-3B | D5: Monthly GST return | E5: Monthly | F5: 07/20/2025 | G5: 🟡 Medium | H5: ✅ Upcoming
A6: India | B6: Pvt. Ltd. | C6: TDS Return (Form 26Q) | D6: Quarterly tax deducted at source filing | E6: Quarterly | F6: 07/31/2025 | G6: 🟡 Medium | H6: ✅ Upcoming
A7: India | B7: Pvt. Ltd. | C7: ROC Annual Filing (AOC-4 & MGT-7) | D7: Registrar of Companies compliance | E7: Annually | F7: 10/30/2025 | G7: 🔴 High | H7: ✅ Upcoming
A8: US | B8: C-Corp | C8: Delaware Franchise Tax | D8: Franchise tax due to Delaware | E8: Annually | F8: 45660 | G8: 🟢 Low | H8: ✅ Upcoming
A9: India | B9: Pvt. Ltd. | C9: Form 3CD Tax Audit Report | D9: Tax audit submission | E9: Annually | F9: 09/30/2025 | G9: 🔴 High | H9: ✅ Upcoming
A10: US | B10: C-Corp | C10: Form W-2 Filing | D10: Wage statements for employees | E10: Annually | F10: 01/31/2025 | G10: 🔴 High | H10: ✅ Upcoming
A11: US | B11: C-Corp | C11: Form W-3 Summary | D11: W-2 summary submission | E11: Annually | F11: 01/31/2025 | G11: 🟡 Medium | H11: ✅ Upcoming
A12: US | B12: C-Corp | C12: Form 1099-NEC Filing | D12: Contractor payments reporting | E12: Annually | F12: 01/31/2025 | G12: 🔴 High | H12: ⚠️ Due Soon
A13: US | B13: C-Corp | C13: Form 1099-MISC Filing | D13: Misc vendor payment reporting | E13: Annually | F13: 02/28/2025 | G13: 🟡 Medium | H13: ⚠️ Due Soon
A14: US | B14: C-Corp | C14: State Annual Report | D14: Maintain state good standing | E14: Annually | F14: 45660 | G14: 🟡 Medium | H14: ✅ Upcoming
A15: US | B15: C-Corp | C15: Registered Agent Renewal | D15: Maintain registered agent | E15: Annually | F15: 12/31/2025 | G15: 🟢 Low | H15: ✅ Upcoming
A16: US | B16: C-Corp | C16: Form 940 (FUTA) | D16: Federal unemployment tax | E16: Annually | F16: 01/31/2025 | G16: 🟡 Medium | H16: ⚠️ Due Soon
A17: US | B17: C-Corp | C17: Monthly Sales Tax Return | D17: Sales tax compliance | E17: Monthly | F17: 02/20/2025 | G17: 🟡 Medium | H17: ⚠️ Due Soon
A18: US | B18: LP | C18: Form 1065 Partnership Return | D18: Annual partnership tax return | E18: Annually | F18: 03/15/2025 | G18: 🔴 High | H18: ✅ Upcoming
A19: US | B19: LP | C19: State LP Annual Renewal | D19: Maintain state LP registration | E19: Annually | F19: 12/31/2025 | G19: 🟢 Low | H19: ✅ Upcoming
A20: US | B20: LP | C20: State Franchise/Partnership Tax | D20: State-level partnership tax | E20: Annually | F20: 03/15/2025 | G20: 🟡 Medium | H20: ⚠️ Due Soon
A21: US | B21: LP | C21: Form 8865 Filing | D21: Foreign partnership reporting | E21: Annually | F21: 04/15/2025 | G21: 🟡 Medium | H21: ⚠️ Due Soon
A22: India | B22: Pvt. Ltd. | C22: EPF Monthly Payment | D22: Employee provident fund payment | E22: Monthly | F22: 45731 | G22: 🔴 High | H22: ⚠️ Due Soon
A23: India | B23: Pvt. Ltd. | C23: ESIC Monthly Return | D23: Employee state insurance filing | E23: Monthly | F23: 45731 | G23: 🟡 Medium | H23: ⚠️ Due Soon
A24: India | B24: Pvt. Ltd. | C24: Professional Tax Return | D24: Monthly PT filing | E24: Monthly | F24: 45746 | G24: 🟢 Low | H24: ✅ Upcoming
A25: India | B25: Pvt. Ltd. | C25: GSTR-9 Annual Return | D25: GST annual compliance | E25: Annually | F25: 46022 | G25: 🟡 Medium | H25: ✅ Upcoming
A26: India | B26: Pvt. Ltd. | C26: GSTR-9C Audit Report | D26: GST audit reconciliation | E26: Annually | F26: 46022 | G26: 🔴 High | H26: ❌ Missed
A27: India | B27: Pvt. Ltd. | C27: Form 16A TDS Certificates | D27: TDS certificates to vendors | E27: Quarterly | F27: 45792 | G27: 🟡 Medium | H27: ✅ Upcoming
A28: India | B28: Pvt. Ltd. | C28: DIR-3 KYC | D28: Director KYC filing | E28: Annually | F28: 45930 | G28: 🟡 Medium | H28: ✅ Upcoming
A29: India | B29: Pvt. Ltd. | C29: Form 3CEB | D29: Transfer pricing report | E29: Annually | F29: 45961 | G29: 🔴 High | H29: ⚠️ Due Soon
A30: India | B30: Pvt. Ltd. | C30: FEMA Annual Return | D30: Foreign investment reporting | E30: Annually | F30: 45853 | G30: 🟡 Medium | H30: ⚠️ Due Soon
A31: India | B31: Pvt. Ltd. | C31: Equalization Levy Return | D31: Levy on cross-border digital services | E31: Annually | F31: 45838 | G31: 🟢 Low | H31: ⚠️ Due Soon
A32: India | B32: Pvt. Ltd. | C32: MSME Form-1 | D32: Half-yearly MSME dues reporting | E32: Semi-Annual | F32: 04/15/2025 | G32: 🟡 Medium | H32: ⚠️ Due Soon
A33: India | B33: Pvt. Ltd. | C33: Board Meeting Minutes Filing | D33: Quarterly board minutes filing | E33: Quarterly | F33: 45762 | G33: 🟢 Low | H33: ⚠️ Due Soon
A34: India | B34: Pvt. Ltd. | C34: MGT-14 Filing | D34: File special resolutions with ROC | E34: Event-based | F34: 45762 | G34: 🟡 Medium | H34: ❌ Missed
A35: US | B35: LP | C35: Form 1065 Partnership Return | D35: Annual partnership tax return | E35: Annually | F35: 03/15/2025 | G35: 🔴 High | H35: ✅ Upcoming
A36: US | B36: LP | C36: State LP Annual Renewal | D36: Maintain state LP registration | E36: Annually | F36: 12/31/2025 | G36: 🟢 Low | H36: ✅ Upcoming
A37: US | B37: LP | C37: State Franchise/Partnership Tax | D37: State-level partnership tax | E37: Annually | F37: 03/15/2025 | G37: 🟡 Medium | H37: ⚠️ Due Soon
A38: US | B38: LP | C38: Form 8865 Filing | D38: Foreign partnership reporting | E38: Annually | F38: 04/15/2025 | G38: 🟡 Medium | H38: ⚠️ Due Soon
A39: India | B39: Pvt. Ltd. | C39: EPF Monthly Payment | D39: Employee provident fund payment | E39: Monthly | F39: 45731 | G39: 🔴 High | H39: ⚠️ Due Soon
A40: India | B40: Pvt. Ltd. | C40: ESIC Monthly Return | D40: Employee state insurance filing | E40: Monthly | F40: 45731 | G40: 🟡 Medium | H40: ⚠️ Due Soon

Sheet Fund_Waterfall
A1: Committed Capital | B1: 500000000
A2: GP Commit % | B2: 0.01
A3: Management Fee % | B3: 0.0075
A4: Fee Basis | B4: Committed
A5: Frequency | B5: Quarterly
A6: Deferred Fee % | B6: 1
A7: Deferred Interest | B7: 0.045
A8: Hurdle | B8: 0.08
A9: GP Carry | B9: 0.2
A10: LP Carry | B10: 0.8
A11: Capital Calls Table | J11: Yearly NAV
A12: Year | B12: Capital Call | C12: Date | E12: Quarterly Mgmt Fee | F12: Deferred Fee | G12: Deferred Fee Interest | H12: Total Fee Charged | J12: Year | K12: Perf % | L12: Start NAV | M12: End NAV | P12: Description | Q12: Formula/Value | S12: Date | T12: Cash Flow
A13: 1 | B13: =250000000 -> 250000000 | C13: 43831 | E13: =$B$1*$B$3/4 -> 937500 | F13: =IF(A13<=2,E13*$B$6,0) -> 937500 | G13: =F13*$B$7 -> 42187.5 | H13: =E13+G13 -> 979687.5 | J13: 1 | K13: 0.1275 | L13: =B13 -> 250000000 | M13: =L13*(1+K13) -> 281875000 | P13: LP Paid-In Capital | Q13: =SUM(B13:B14) -> 500000000 | S13: 43831 | T13: -250000000
A14: 2 | B14: =250000000 -> 250000000 | C14: 44197 | E14: =$B$1*$B$3/4 -> 937500 | F14: =IF(A14<=2,E14*$B$6,0) -> 937500 | G14: =F14*$B$7 -> 42187.5 | H14: =E14+G14 -> 979687.5 | J14: 2 | K14: -0.0263 | L14: =M13 -> 281875000 | M14: =L14*(1+K14) -> 2.7446169e+08 | P14: Total Distributable Cash | Q14: =M17 -> 3.024063e+08 | S14: 44197 | T14: -250000000
J15: 3 | K15: 0.2087 | L15: =M14 -> 2.7446169e+08 | M15: =(L15*(1+K15))-100000000 -> 2.3174184e+08 | P15: Return of Capital | Q15: =MIN(Q14,Q13) -> 3.024063e+08 | S15: 44562 | T15: 0
J16: 4 | K16: 0.0975 | L16: =M15 -> 2.3174184e+08 | M16: =L16*(1+K16) -> 2.5433667e+08 | P16: Excess Cash After Capital Return | Q16: =Q14-Q15 -> 0 | S16: 44927 | T16: 0
J17: 5 | K17: 0.189 | L17: =M16 -> 2.5433667e+08 | M17: =L17*(1+K17) -> 3.024063e+08 | P17: Hurdle Amount | Q17: =Q13*$B$8*5 -> 200000000 | S17: 45292 | T17: 0
L18: =M17 -> 3.024063e+08 | P18: Hurdle Paid | Q18: =MIN(Q16,Q17) -> 0 | S18: 45657 | T18: =M17 -> 3.024063e+08
P19: Post-Hurdle Residual | Q19: =Q16-Q18 -> 0
P20: GP Carry (20%) | Q20: =Q19*$B$9 -> 0 | S20: =IFERROR(__xludf.DUMMYFUNCTION("ISDATE(S18)"),TRUE) -> TRUE
P21: LP Carry (80%) | Q21: =Q19*$B$10 -> 0
P25: DPI | Q25: =(Q15+Q21)/Q13 -> 0.6048126
P26: TVPI | Q26: =(Q14)/Q13 -> 0.6048126
P27: MOIC | Q27: =Q14/Q13 -> 0.6048126
P28: Gross IRR | Q28: =XIRR(T13:T18,S13:S18) -> -0.1060075
P39: Cov(Fund,Market0/Var(Market)
P40: Beta (β) | Q40: =IFERROR(COVAR(C51:C1876,E51:E1876)/VAR(E51:E1876), " ") -> 0.00040365718
P41: VaR 95% | Q41: =PERCENTILE(C51:C1876,0.05) -> -7.2054795e-05
P42: Sharpe Ratio | Q42: =(AVERAGE(C51:C1876)-AVERAGE(G51:G1876))/STDEV(C51:C1876) -> 0.77296421
A49: Daily Dates | B49: Daily Fund NAV | C49: Daily Fund Returns | D49: S&P500 Close | E49: S&P Daily Return | F49: SOFR Daily Rate % | G49: SOFR Daily Return | H49: CLEAN S&P CLOSE (personal use)
A50: 43831 | B50: =L13 -> 250000000 | C50: =" " | D50: 3265.35 | E50: =IF(D50=0, "", D51/D50 - 1) -> 0 | F50: 0.10059378 | G50: =IF(F50="", "", F50/100/365) -> 2.755994e-06 | H50: =IFERROR(VALUE(D50),"") -> 3265.35
A51: =A50+1 -> 43832 | B51: =B50* (1+IF(YEAR(A51)=2020,0.1275/365,IF(YEAR(A51)=2021,-0.0263/365,IF(YEAR(A51)=2022,0.2087/365,IF(YEAR(A51)=2023,0.975/365,0.189/365))))) -> 2.5008733e+08 | C51: =B51/B50-1 -> 0.00034931507 | D51: 3265.35 | E51: =IF(D51=0, "", D52/D51 - 1) -> 0 | F51: 0.10067887 | G51: =IF(F51="", "", F51/100/365) -> 2.7583252e-06 | H51: =IFERROR(VALUE(D51),"") -> 3265.35
A52: =A51+1 -> 43833 | B52: =B51* (1+IF(YEAR(A52)=2020,0.1275/365,IF(YEAR(A52)=2021,-0.0263/365,IF(YEAR(A52)=2022,0.2087/365,IF(YEAR(A52)=2023,0.975/365,0.189/365))))) -> 250174688 | C52: =B52/B51-1 -> 0.00034931507 | D52: 3265.35 | E52: =IF(D52=0, "", D53/D52 - 1) -> 0 | F52: 0.084710082 | G52: =IF(F52="", "", F52/100/365) -> 2.3208242e-06 | H52: =IFERROR(VALUE(D52),"") -> 3265.35
A53: =A52+1 -> 43834 | B53: =B52* (1+IF(YEAR(A53)=2020,0.1275/365,IF(YEAR(A53)=2021,-0.0263/365,IF(YEAR(A53)=2022,0.2087/365,IF(YEAR(A53)=2023,0.975/365,0.189/365))))) -> 2.5026208e+08 | C53: =B53/B52-1 -> 0.00034931507 | D53: 3265.35 | E53: =IF(D53=0, "", D54/D53 - 1) -> 0 | F53: 0.11407991 | G53: =IF(F53="", "", F53/100/365) -> 3.1254769e-06 | H53: =IFERROR(VALUE(D53),"") -> 3265.35
A54: =A53+1 -> 43835 | B54: =B53* (1+IF(YEAR(A54)=2020,0.1275/365,IF(YEAR(A54)=2021,-0.0263/365,IF(YEAR(A54)=2022,0.2087/365,IF(YEAR(A54)=2023,0.975/365,0.189/365))))) -> 2.503495e+08 | C54: =B54/B53-1 -> 0.00034931507 | D54: 3265.35 | E54: =IF(D54=0, "", D55/D54 - 1) -> 0 | F54: 0.10322464 | G54: =IF(F54="", "", F54/100/365) -> 2.8280723e-06 | H54: =IFERROR(VALUE(D54),"") -> 3265.35
A55: =A54+1 -> 43836 | B55: =B54* (1+IF(YEAR(A55)=2020,0.1275/365,IF(YEAR(A55)=2021,-0.0263/365,IF(YEAR(A55)=2022,0.2087/365,IF(YEAR(A55)=2023,0.975/365,0.189/365))))) -> 250436949 | C55: =B55/B54-1 -> 0.00034931507 | D55: 3265.35 | E55: =IF(D55=0, "", D56/D55 - 1) -> 0 | F55: 0.11243211 | G55: =IF(F55="", "", F55/100/365) -> 3.0803319e-06 | H55: =IFERROR(VALUE(D55),"") -> 3265.35
A56: =A55+1 -> 43837 | B56: =B55* (1+IF(YEAR(A56)=2020,0.1275/365,IF(YEAR(A56)=2021,-0.0263/365,IF(YEAR(A56)=2022,0.2087/365,IF(YEAR(A56)=2023,0.975/365,0.189/365))))) -> 2.5052443e+08 | C56: =B56/B55-1 -> 0.00034931507 | D56: 3265.35 | E56: =IF(D56=0, "", D57/D56 - 1) -> 0 | F56: 0.10697656 | G56: =IF(F56="", "", F56/100/365) -> 2.9308646e-06 | H56: =IFERROR(VALUE(D56),"") -> 3265.35
A57: =A56+1 -> 43838 | B57: =B56* (1+IF(YEAR(A57)=2020,0.1275/365,IF(YEAR(A57)=2021,-0.0263/365,IF(YEAR(A57)=2022,0.2087/365,IF(YEAR(A57)=2023,0.975/365,0.189/365))))) -> 2.5061194e+08 | C57: =B57/B56-1 -> 0.00034931507 | D57: 3265.35 | E57: =IF(D57=0, "", D58/D57 - 1) -> 0 | F57: 0.088062578 | G57: =IF(F57="", "", F57/100/365) -> 2.4126734e-06 | H57: =IFERROR(VALUE(D57),"") -> 3265.35
A58: =A57+1 -> 43839 | B58: =B57* (1+IF(YEAR(A58)=2020,0.1275/365,IF(YEAR(A58)=2021,-0.0263/365,IF(YEAR(A58)=2022,0.2087/365,IF(YEAR(A58)=2023,0.975/365,0.189/365))))) -> 2.5069948e+08 | C58: =B58/B57-1 -> 0.00034931507 | D58: 3265.35 | E58: =IF(D58=0, "", D59/D58 - 1) -> 0 | F58: 0.10370584 | G58: =IF(F58="", "", F58/100/365) -> 2.8412559e-06 | H58: =IFERROR(VALUE(D58),"") -> 3265.35
A59: =A58+1 -> 43840 | B59: =B58* (1+IF(YEAR(A59)=2020,0.1275/365,IF(YEAR(A59)=2021,-0.0263/365,IF(YEAR(A59)=2022,0.2087/365,IF(YEAR(A59)=2023,0.975/365,0.189/365))))) -> 250787058 | C59: =B59/B58-1 -> 0.00034931507 | D59: 3265.35 | E59: =IF(D59=0, "", D60/D59 - 1) -> 0 | F59: 0.11085975 | G59: =IF(F59="", "", F59/100/365) -> 3.0372534e-06 | H59: =IFERROR(VALUE(D59),"") -> 3265.35
...
